Workbook

Sheet 시트1
A1: 4조 이클립스
A2: =IFERROR(Concatenate("Project Period : ",TEXT(MIN(H$7:$I1000),"YY년 M월 D일"),"~",TEXT(Max(I$7:$J1000),"YY년 M월 D일")),"")
A3: Group | B3: Task | C3: Subtask | D3: Description | E3: Link | F3: Team | G3: Assignee | H3: Start Date | I3: End Date | J3: Period | K3: Status | L3: Progress | M3: =TEXT(M4,"mmm") -> 9월 | W3: =TEXT(W4,"mmm") -> 9월 | AQ3: =TEXT(AQ4,"mmm") -> 10월 | BC3: =TEXT(BC4,"mmm") -> 11월 | BZ3: =TEXT(BZ4,"mmm") -> 12월 | CT3: =TEXT(CT4,"mmm") -> 1월
M4: =H5-weekday(H5,2)+1 -> 45915 | N4: =M4+1 -> 45916 | O4: =N4+1 -> 45917 | P4: =O4+1 -> 45918 | Q4: =P4+1 -> 45919 | R4: =Q4+3 -> 45922 | S4: =R4+1 -> 45923 | T4: =S4+1 -> 45924 | U4: =T4+1 -> 45925 | V4: =U4+1 -> 45926 | W4: =V4+3 -> 45929 | X4: =W4+1 -> 45930 | Y4: =X4+1 -> 45931 | Z4: =Y4+1 -> 45932 | AA4: =Z4+1 -> 45933 | AB4: =AA4+3 -> 45936 | AC4: =AB4+1 -> 45937 | AD4: =AC4+1 -> 45938 | AE4: =AD4+1 -> 45939 | AF4: =AE4+1 -> 45940 | AG4: =AF4+3 -> 45943 | AH4: =AG4+1 -> 45944 | AI4: =AH4+1 -> 45945 | AJ4: =AI4+1 -> 45946 | AK4: =AJ4+1 -> 45947 | AL4: =AK4+3 -> 45950 | AM4: =AL4+1 -> 45951 | AN4: =AM4+1 -> 45952 | AO4: =AN4+1 -> 45953 | AP4: =AO4+1 -> 45954 | AQ4: =AP4+3 -> 45957 | AR4: =AQ4+1 -> 45958 | AS4: =AR4+1 -> 45959 | AT4: =AS4+1 -> 45960 | AU4: =AT4+1 -> 45961 | AV4: =AU4+3 -> 45964 | AW4: =AV4+1 -> 45965 | AX4: =AW4+1 -> 45966 | AY4: =AX4+1 -> 45967 | AZ4: =AY4+1 -> 45968 | BA4: =AZ4+3 -> 45971 | BB4: =BA4+1 -> 45972 | BC4: =BB4+1 -> 45973 | BD4: =BC4+1 -> 45974 | BE4: =BD4+1 -> 45975 | BF4: =BE4+3 -> 45978 | BG4: =BF4+1 -> 45979 | BH4: =BG4+1 -> 45980 | BI4: =BH4+1 -> 45981 | BJ4: =BI4+1 -> 45982 | BK4: =BJ4+3 -> 45985 | BL4: =BK4+1 -> 45986 | BM4: =BL4+1 -> 45987 | BN4: =BM4+1 -> 45988 | BO4: =BN4+1 -> 45989 | BP4: =BO4+3 -> 45992 | BQ4: =BP4+1 -> 45993 | BR4: =BQ4+1 -> 45994 | BS4: =BR4+1 -> 45995 | BT4: =BS4+1 -> 45996 | BU4: =BT4+3 -> 45999 | BV4: =BU4+1 -> 46000 | BW4: =BV4+1 -> 46001 | BX4: =BW4+1 -> 46002 | BY4: =BX4+1 -> 46003 | BZ4: =BY4+3 -> 46006 | CA4: =BZ4+1 -> 46007 | CB4: =CA4+1 -> 46008 | CC4: =CB4+1 -> 46009 | CD4: =CC4+1 -> 46010 | CE4: =CD4+3 -> 46013 | CF4: =CE4+1 -> 46014 | CG4: =CF4+1 -> 46015 | CH4: =CG4+1 -> 46016 | CI4: =CH4+1 -> 46017 | CJ4: =CI4+3 -> 46020 | CK4: =CJ4+1 -> 46021 | CL4: =CK4+1 -> 46022 | CM4: =CL4+1 -> 46023 | CN4: =CM4+1 -> 46024 | CO4: =CN4+3 -> 46027 | CP4: =CO4+1 -> 46028 | CQ4: =CP4+1 -> 46029 | CR4: =CQ4+1 -> 46030 | CS4: =CR4+1 -> 46031 | CT4: =CS4+3 -> 46034 | CU4: =CT4+1 -> 46035 | CV4: =CU4+1 -> 46036 | CW4: =CV4+1 -> 46037 | CX4: =CW4+1 -> 46038 | CY4: =CX4+3 -> 46041 | CZ4: =CY4+1 -> 46042 | DA4: =CZ4+1 -> 46043 | DB4: =DA4+1 -> 46044 | DC4: =DB4+1 -> 46045 | DD4: =DC4+3 -> 46048 | DE4: =DD4+1 -> 46049 | DF4: =DE4+1 -> 46050 | DG4: =DF4+1 -> 46051 | DH4: =DG4+1 -> 46052 | DI4: =DH4+3 -> 46055 | DJ4: =DI4+1 -> 46056 | DK4: =DJ4+1 -> 46057 | DL4: =DK4+1 -> 46058 | DM4: =DL4+1 -> 46059 | DN4: =DM4+3 -> 46062 | DO4: =DN4+1 -> 46063 | DP4: =DO4+1 -> 46064
A5: 킥오프 | H5: 45919 | I5: 45926 | J5: =IF(C5="","",NETWORKDAYS(H5,I5,Filter!D$2:D1000)) | K5: 완료
A6: 9월 19일~ | B6: 초기설정 | C6: 주제선정 | G6: 전원 | H6: 45919 | I6: 45919 | J6: =IF(C6="","",NETWORKDAYS(H6,I6,Filter!D$2:D1001)) -> #REF! | K6: 완료
C7: 그라운드룰 작성 | E7: 노션 | G7: 전원 | H7: 45919 | I7: 45919 | J7: =IF(C7="","",NETWORKDAYS(H7,I7,Filter!D$2:D1002)) -> #REF! | K7: 완료
C8: 개발 소스 저장소 (깃) 만들기 | E8: 깃 | G8: 전원 | H8: 45919 | I8: 45919 | J8: =IF(C8="","",NETWORKDAYS(H8,I8,Filter!D$2:D1003)) -> #REF! | K8: 완료
C9: 스프린트 확정 | G9: 전원 | H9: 45919 | I9: 45919 | J9: =IF(C9="","",NETWORKDAYS(H9,I9,Filter!D$2:D1004)) -> #REF! | K9: 완료
C10: 프로젝트 관리 도구 (노션) 정리 | E10: 노션 | G10: 전원 | H10: 45919 | I10: 45919 | J10: =IF(C10="","",NETWORKDAYS(H10,I10,Filter!D$2:D1005)) -> #REF! | K10: 완료
C11: 산출물 저장소 (노션) 만들기 | E11: 노션 | G11: 전원 | H11: 45919 | I11: 45923 | J11: =IF(C11="","",NETWORKDAYS(H11,I11,Filter!D$2:D1006)) -> #REF! | K11: 완료
A12: S1 | H12: 45919 | I12: 45926 | J12: =IF(C12="","",NETWORKDAYS(H12,I12,Filter!D$2:D1007)) | K12: 완료
A13: 9월 23일 ~ 9월 30일 | B13: 기획 | C13: 프로젝트 기획서 | D13: 프로젝트 개요 | E13: 프로젝트 기획서 | G13: 전원 | H13: 45919 | I13: 45923 | J13: =IF(C13="","",NETWORKDAYS(H13,I13,Filter!D$2:D1008)) -> #REF! | K13: 완료
D14: 주요 추천 카테고리 | H14: 45919 | I14: 45923 | J14: =IF(C14="","",NETWORKDAYS(H14,I14,Filter!D$2:D1009)) | K14: 완료
D15: 추천로직 고려요소 | H15: 45919 | I15: 45923 | J15: =IF(C15="","",NETWORKDAYS(H15,I15,Filter!D$2:D1010)) | K15: 완료
D16: 기능 | H16: 45919 | I16: 45923 | J16: =IF(C16="","",NETWORKDAYS(H16,I16,Filter!D$2:D1011)) | K16: 완료
D17: 서비스 흐름 | H17: 45919 | I17: 45923 | J17: =IF(C17="","",NETWORKDAYS(H17,I17,Filter!D$2:D1012)) | K17: 완료
D18: 기대효과 | H18: 45919 | I18: 45923 | J18: =IF(C18="","",NETWORKDAYS(H18,I18,Filter!D$2:D1013)) | K18: 완료
C19: 요구사항 정의서 | D19: 프로젝트 개요 | E19: 요구사항 정의서 | G19: 홍수현, 장승원 | H19: 45923 | I19: 45923 | J19: =IF(C19="","",NETWORKDAYS(H19,I19,Filter!D$2:D1014)) -> #REF! | K19: 완료
D20: 기능 요구사항 | G20: 장승원, 홍수현 | H20: 45923 | I20: 45923 | J20: =IF(C20="","",NETWORKDAYS(H20,I20,Filter!D$2:D1015)) | K20: 완료
D21: 비기능 요구사항 | G21: 홍수현, 사석훈, 장승원 | H21: 45923 | I21: 45923 | J21: =IF(C21="","",NETWORKDAYS(H21,I21,Filter!D$2:D1016)) | K21: 완료
D22: 제약사항 및 가정 | G22: 홍수현, 사석훈, 장승원 | H22: 45923 | I22: 45923 | J22: =IF(C22="","",NETWORKDAYS(H22,I22,Filter!D$2:D1017)) | K22: 완료
D23: 추후 추가 기능 업데이트 | G23: 전원 | H23: 45923 | I23: 45923 | J23: =IF(C23="","",NETWORKDAYS(H23,I23,Filter!D$2:D1018)) | K23: 완료
B24: 계획 | C24: API 명세서 | D24: 공통 | E24: API 명세서 | G24: 사석훈 | H24: 45924 | I24: 45925 | J24: =IF(C24="","",NETWORKDAYS(H24,I24,Filter!D$2:D1019)) -> #REF! | K24: 완료
D25: 메인 서버 - 어플리케이션 | H25: 45924 | I25: 45925 | J25: =IF(C25="","",NETWORKDAYS(H25,I25,Filter!D$2:D1020)) | K25: 완료
D26: 커뮤니티 서버 - 어플리케이션 | H26: 45924 | I26: 45925 | J26: =IF(C26="","",NETWORKDAYS(H26,I26,Filter!D$2:D1021)) | K26: 완료
C27: 시스템 아키텍처 | E27: 노션 | G27: 전원 | H27: 45925 | I27: 45925 | J27: =IF(C27="","",NETWORKDAYS(H27,I27,Filter!D$2:D1022)) -> #REF! | K27: 완료
C28: 사용자 시나리오 | E28: 노션 | G28: 사석훈 | H28: 45925 | I28: 45925 | J28: =IF(C28="","",NETWORKDAYS(H28,I28,Filter!D$2:D1023)) -> #REF! | K28: 완료
C29: 사용자 흐름도 | E29: 노션 | G29: 전원 | H29: 45925 | I29: 45925 | J29: =IF(C29="","",NETWORKDAYS(H29,I29,Filter!D$2:D1024)) -> #REF! | K29: 완료
C30: 서비스 흐름도 | G30: 사석훈 | H30: 45925 | I30: 45925 | J30: =IF(C30="","",NETWORKDAYS(H30,I30,Filter!D$2:D1025)) -> #REF! | K30: 완료
C31: 레퍼런스 리서치 | E31: 노션 | G31: 장승원, 홍수현 | H31: 45923 | I31: 45925 | J31: =IF(C31="","",NETWORKDAYS(H31,I31,Filter!D$2:D1026)) -> #REF! | K31: 완료
C32: 파인튜닝? | D32: 하루 프롬프트 회의 | G32: 전원 | H32: 45925 | I32: 45925 | J32: =IF(C32="","",NETWORKDAYS(H32,I32,Filter!D$2:D1027)) -> #REF! | K32: 완료
B33: 데이터 모델링 | C33: 물리 ERD | E33: ERD | G33: 사석훈 | H33: 45924 | I33: 45926 | J33: =IF(C33="","",NETWORKDAYS(H33,I33,Filter!D$2:D1028)) -> #REF! | K33: 완료
C34: 논리 ERD | G34: 홍수현, 장승원 | H34: 45926 | I34: 45926 | J34: =IF(C34="","",NETWORKDAYS(H34,I34,Filter!D$2:D1029)) -> #REF! | K34: 완료
B35: POC1 | C35: 크롤링 | D35: 네이버지도 | G35: 조설훈 | H35: 45924 | I35: 45926 | J35: =IF(C35="","",NETWORKDAYS(H35,I35,Filter!D$2:D1030)) -> #REF! | K35: 완료
D36: 카카오지도 | G36: 조설훈 | H36: 45924 | I36: 45926 | J36: =IF(C36="","",NETWORKDAYS(H36,I36,Filter!D$2:D1031)) | K36: 완료
C37: 어플 프로토타입 | D37: 피그마, 스티치로 제작 | E37: 프로토타입 | G37: 장승원, 홍수현 | H37: 45926 | I37: 45927 | J37: =IF(C37="","",NETWORKDAYS(H37,I37,Filter!D$2:D1032)) -> #REF! | K37: 완료
B38: 앱 개발 환경 구축 | C38: 사용할 프레임워크 정하기 | G38: 장승원, 홍수현 | H38: 45929 | I38: 45929 | J38: =IF(C38="","",NETWORKDAYS(H38,I38,Filter!D$2:D1033)) -> #REF! | K38: 완료
C39: 프레임 워크 테스트 | G39: 홍수현, 장승원 | H39: 45929 | I39: 45930 | J39: =IF(C39="","",NETWORKDAYS(H39,I39,Filter!D$2:D1034)) -> #REF! | K39: 완료
C40: 모의 개발 | G40: 홍수현, 장승원 | H40: 45929 | I40: 45930 | J40: =IF(C40="","",NETWORKDAYS(H40,I40,Filter!D$2:D1035)) -> #REF! | K40: 완료
...
